Workbook

Sheet 00_README
A1: 관세범죄 지식 레지스트리 — 시스템 적재용 마스터
A2: 작성 기준일 | B2: 2026-08-07 / 초안 v0.1
A3: 용도 | B3: 포털 「범죄유형 지식화 + 증거수집 가이드」 기능의 기준 마스터 데이터
A5: 시트 | B5: 내용 | C5: 행 수 | D5: 적재 순서
A6: 01_C_죄명 | B6: 죄명 마스터 — 근거조문·행위태양·가중근거·소추조건 | C6: =COUNTA('01_C_죄명'!$A$2:$A$2000) -> 19 | D6: 1
A7: 02_F_요증사실 | B7: 요증사실 마스터 — 죄명별 3계층(F-O 객관 / F-S 주관 / F-P 절차) 분해 | C7: =COUNTA('02_F_요증사실'!$A$2:$A$2000) -> 50 | D7: 2
A8: 03_E_증거항목 | B8: 증거항목 마스터 — 보유주체·휘발성·기본 게이트 | C8: =COUNTA('03_E_증거항목'!$A$2:$A$2000) -> 56 | D8: 3
A9: 04_A_수집행위 | B9: 수집행위 마스터 — 근거법령·게이트·산출물·소요기간 | C9: =COUNTA('04_A_수집행위'!$A$2:$A$2000) -> 16 | D9: 4
A10: 05_MAP_F-E-A | B10: 핵심 매핑 — F를 키로 증거항목·수집행위·게이트를 연결 | C10: =COUNTA('05_MAP_F-E-A'!$A$2:$A$2000) -> 128 | D10: 5
A11: 06_P_패턴 | B11: 수법 패턴 카탈로그 — 앵커·조건절·반증조건·실행구분 | C11: =COUNTA('06_P_패턴'!$A$2:$A$2000) -> 15 | D11: 6
A12: 07_TAG_태그체계 | B12: 다면 태그 — 구조/앵커/축/게이트/업종/채널/휘발성/상태 | C12: =COUNTA('07_TAG_태그체계'!$A$2:$A$2000) -> 47 | D12: 3
A13: 08_G_게이트 | B13: 권한 게이트 정의 — G1~G4 | C13: =COUNTA('08_G_게이트'!$A$2:$A$2000) -> 4 | D13: 3
A14: 09_R_규칙 | B14: 운영 규칙 — 패턴(R1~R10) / 죄명(R-C) / 증거(R-E) | C14: =COUNTA('09_R_규칙'!$A$2:$A$2000) -> 22 | D14: 7
A16: 코드 체계
A17: C-{대분류2}{일련2} | B17: 죄명 — 법령 개정 시에만 변경 (고정 자산)
A18: F-{죄명}-{일련2} | B18: 요증사실 — 구성요건에서 도출 (고정 자산)
A19: E-{일련3} | B19: 증거항목 — 죄명에 종속시키지 않음 (공용 자산)
A20: A-{일련2} | B20: 수집행위 — 죄명에 종속시키지 않음 (공용 자산)
A21: P-{일련3}.v{버전} | B21: 패턴 — 상시 등록·폐기 (증식 자산)
A22: M-{죄명}-{일련2} | B22: 수법 — 죄명과 패턴을 잇는 축
A24: 연결 체인
A25: 탐지 체인 | B25: M 수법 → P 패턴 → 피처(A~D) → 적중
A26: 입증 체인 | B26: C 죄명 → F 요증사실 → E 증거 → A 수집행위(+G 게이트)
A27: 접합점 | B27: 두 체인은 M ↔ C 지점에서만 만남 → 06_P_패턴의 「연결 C코드」가 접합 키
A29: 미확정 항목 (운영 전 법무 검토 필요)
B30: 특가법 제6조의 항·호별 대응관계와 기준액 — 죄명별로 현행 조문 확인 필요
B31: 특가법 적용 시 고발 요건 배제 범위 — F-GEN-04의 죄명별 적용 여부가 갈림
B32: 개별법(C-51·C-52·C-61~63) 죄명의 소관 부처 및 고발·고소 주체
B33: 01_C_죄명 중 「미전개(2차)」 10건의 F 세트 작성
B34: 06_P_패턴 15건 전부 반증조건 미작성 — R4에 따라 현재 운영 승인 불가 상태
A36: 적재 시 유의
B37: 05_MAP_F-E-A가 본체이며, F코드·E코드·A코드는 각 마스터 시트의 외래키임
B38: 필수구분 ◎는 해당 요증사실의 필수 증거, ○는 방어 대비 보강 증거
B39: 음영 처리된 행·셀은 미완성 또는 주의 항목 (F-S 계층, G3·G4 게이트, 휘발성 상, 반증조건 미작성)
B40: 01·02 시트의 우측 건수 열은 수식이므로 행 추가 시 범위 확인 필요

Sheet 01_C_죄명
A1: C코드 | B1: 대분류 | C1: 죄명 | D1: 근거법률 | E1: 근거조문 | F1: 행위 태양 | G1: 가중 근거 | H1: 선결 죄명 | I1: 소추조건 | J1: 몰수·추징 | K1: F 전개상태 | L1: 연결 F 건수
A2: C-11 | B2: 관세수입 침해 | C2: 관세포탈 | D2: 관세법 | E2: 제270조①1 | F2: 세액결정에 영향을 미치기 위해 과세가격·관세율 등을 거짓신고하거나 신고하지 않고 수입 | G2: 특가법 제6조 | I2: 세관장 고발 | J2: 해당 없음 | K2: 완료 | L2: =COUNTIF('02_F_요증사실'!$B$2:$B$1000,A2) -> 7
A3: C-12 | B3: 관세수입 침해 | C3: 부정감면 | D3: 관세법 | E3: 제270조④ | F3: 부정한 방법으로 관세를 감면받거나 감면물품에 대한 관세 징수를 면탈 | G3: 특가법 제6조 | I3: 세관장 고발 | J3: 해당 없음 | K3: 완료 | L3: =COUNTIF('02_F_요증사실'!$B$2:$B$1000,A3) -> 5
A4: C-13 | B4: 관세수입 침해 | C4: 부정환급 | D4: 관세법 | E4: 제270조⑤ | F4: 부정한 방법으로 관세를 환급받음 (세관장은 해당 세액 즉시 징수) | G4: 특가법 제6조 | I4: 세관장 고발 | J4: 해당 없음 | K4: 완료 | L4: =COUNTIF('02_F_요증사실'!$B$2:$B$1000,A4) -> 5
A5: C-14 | B5: 관세수입 침해 | C5: 가격조작 | D5: 관세법 | E5: 제270조의2 | F5: 재산상 이득 취득 목적으로 물품가격을 조작하여 신청·신고 | G5: － | I5: 세관장 고발 | J5: 해당 없음 | K5: 완료 | L5: =COUNTIF('02_F_요증사실'!$B$2:$B$1000,A5) -> 4
A6: C-21 | B6: 밀수출입 | C6: 밀수입 | D6: 관세법 | E6: 제269조②1·2 | F6: 무신고 수입 / 해당 수입물품과 다른 물품으로 신고하여 수입 | G6: 특가법 제6조 | I6: 세관장 고발 | J6: 몰수, 불능 시 국내도매가격 추징 | K6: 완료 | L6: =COUNTIF('02_F_요증사실'!$B$2:$B$1000,A6) -> 6
A7: C-22 | B7: 밀수출입 | C7: 밀수출·밀반송 | D7: 관세법 | E7: 제269조③1·2 | F7: 무신고 수출·반송 / 다른 물품으로 신고하여 수출·반송 | G7: 특가법 제6조 | I7: 세관장 고발 | J7: 몰수 대상 | K7: 미전개(2차) | L7: =COUNTIF('02_F_요증사실'!$B$2:$B$1000,A7) -> 0
A8: C-23 | B8: 밀수출입 | C8: 금지품 수출입 | D8: 관세법 | E8: 제269조① (제234조 각 호) | F8: 수출입 금지품의 수출 또는 수입 | G8: 특가법 제6조① | I8: 세관장 고발 | J8: 몰수 대상 | K8: 미전개(2차) | L8: =COUNTIF('02_F_요증사실'!$B$2:$B$1000,A8) -> 0
A9: C-24 | B9: 밀수출입 | C9: 밀수품 취득 등 | D9: 관세법 | E9: 제274조① | F9: 밀수품의 취득·양도·운반·보관·알선 또는 감정 | G9: 특가법 제6조 | H9: C-21 / C-22 / C-23 | I9: 세관장 고발 | J9: 몰수·추징 대상 | K9: 완료 | L9: =COUNTIF('02_F_요증사실'!$B$2:$B$1000,A9) -> 4
A10: C-31 | B10: 부정 통관·신고 | C10: 부정수입 | D10: 관세법 | E10: 제270조② | F10: 수입에 필요한 허가·승인·추천·증명 등을 갖추지 않거나 부정한 방법으로 갖추어 수입 | G10: 특가법 제6조 | I10: 세관장 고발 | J10: 해당 없음 | K10: 완료 | L10: =COUNTIF('02_F_요증사실'!$B$2:$B$1000,A10) -> 4
A11: C-32 | B11: 부정 통관·신고 | C11: 부정수출 | D11: 관세법 | E11: 제270조③ | F11: 수출·반송에 필요한 요건을 갖추지 않거나 부정한 방법으로 갖추어 수출·반송 | G11: － | I11: 세관장 고발 | J11: 해당 없음 | K11: 미전개(2차) | L11: =COUNTIF('02_F_요증사실'!$B$2:$B$1000,A11) -> 0
A12: C-33 | B12: 부정 통관·신고 | C12: 분할수입 등 회피 | D12: 관세법 | E12: 제270조①3 | F12: 수입제한 회피 목적의 부분품 수입 또는 완제품 분할수입 | G12: － | I12: 세관장 고발 | J12: 해당 없음 | K12: 미전개(2차) | L12: =COUNTIF('02_F_요증사실'!$B$2:$B$1000,A12) -> 0
A13: C-34 | B13: 통관·절차 질서 | C13: 허위신고 | D13: 관세법 | E13: 제276조 | F13: 신고사항의 미신고 또는 허위신고 (세액·통관적정 주요사항 외) | G13: － | I13: 세관장 고발 | J13: 해당 없음 | K13: 미전개(2차) | L13: =COUNTIF('02_F_요증사실'!$B$2:$B$1000,A13) -> 0
A14: C-41 | B14: 통관·절차 질서 | C14: 명의대여 | D14: 관세법 | E14: 제275조의3 | F14: 관세 회피·강제집행 면탈·재산상 이득 목적의 타인 명의 납세신고 및 그 허락 | G14: － | I14: 세관장 고발 | J14: 해당 없음 | K14: 완료 | L14: =COUNTIF('02_F_요증사실'!$B$2:$B$1000,A14) -> 4
A15: C-42 | B15: 통관·절차 질서 | C15: 강제징수 면탈 | D15: 관세법 | E15: 제275조의2 | F15: 재산 은닉·탈루 또는 거짓계약으로 강제징수를 면탈 | G15: － | I15: 세관장 고발 | J15: 해당 없음 | K15: 미전개(2차) | L15: =COUNTIF('02_F_요증사실'!$B$2:$B$1000,A15) -> 0
A16: C-51 | B16: 금지·제한 위반 | C16: 원산지표시 위반 | D16: 대외무역법 | E16: 제33조 등 | F16: 원산지 허위표시·오인표시, 표시의 손상·변경 | G16: － | I16: 소관 부처 확인 필요 | J16: 해당 없음 | K16: 미전개(2차) | L16: =COUNTIF('02_F_요증사실'!$B$2:$B$1000,A16) -> 0
A17: C-52 | B17: 금지·제한 위반 | C17: 지재권 침해물품 수입 | D17: 상표법·저작권법 등 | E17: 상표법 제230조 등 | F17: 침해물품의 수입·유통 (관세법 제235조 통관보류 연계) | G17: － | I17: 권리자 고소 여부 확인 | J17: 몰수 가능 | K17: 미전개(2차) | L17: =COUNTIF('02_F_요증사실'!$B$2:$B$1000,A17) -> 0
A18: C-61 | B18: 외환수사 | C18: 신고 없는 지급방법 | D18: 외국환거래법 | E18: 제16조 등 | F18: 환치기 등 신고하지 않은 지급·수령 방법에 의한 자금이동 | G18: － | I18: 별도 확인 | J18: 몰수·추징 가능 | K18: 완료 | L18: =COUNTIF('02_F_요증사실'!$B$2:$B$1000,A18) -> 5
A19: C-62 | B19: 외환수사 | C19: 무등록 외국환업무 | D19: 외국환거래법 | E19: 제8조 등 | F19: 등록 없이 환전·송금 등 외국환업무 영위 | G19: － | I19: 별도 확인 | J19: 몰수·추징 가능 | K19: 미전개(2차) | L19: =COUNTIF('02_F_요증사실'!$B$2:$B$1000,A19) -> 0
A20: C-63 | B20: 외환수사 | C20: 재산국외도피 | D20: 특경법 | E20: 제4조 | F20: 법령을 위반하여 재산을 국외로 이동하거나 국내로 반입하지 않음 | G20: 특경법 자체 가중 | I20: 별도 확인 | J20: 몰수·추징 대상 | K20: 미전개(2차) | L20: =COUNTIF('02_F_요증사실'!$B$2:$B$1000,A20) -> 0

Sheet 02_F_요증사실
A1: F코드 | B1: C코드 | C1: 계층 | D1: 요증사실 | E1: 입증 난이도 | F1: 비고 | G1: 매핑 E 건수
A2: F-C11-01 | B2: C-11 | C2: F-O | D2: 수입신고를 한 사실 (신고인·신고번호 특정) | E2: 하 | G2: =COUNTIF('05_MAP_F-E-A'!$B$2:$B$2000,A2) -> 2
A3: F-C11-02 | B3: C-11 | C3: F-O | D3: 신고내용이 사실과 다름 — 과세가격·세번·세율·수량·원산지 중 무엇이 어떻게 다른지 특정 | E3: 중 | G3: =COUNTIF('05_MAP_F-E-A'!$B$2:$B$2000,A3) -> 5
A4: F-C11-03 | B4: C-11 | C4: F-O | D4: 물품의 동일성은 유지됨 (동일성 부정 시 C-21로 이동) | E4: 중 | F4: R-C1 분기점 | G4: =COUNTIF('05_MAP_F-E-A'!$B$2:$B$2000,A4) -> 3
A5: F-C11-04 | B5: C-11 | C5: F-O | D5: 정당세액과 신고세액의 차액 = 포탈세액 | E5: 중 | G5: =COUNTIF('05_MAP_F-E-A'!$B$2:$B$2000,A5) -> 3
A6: F-C11-05 | B6: C-11 | C6: F-S | D6: 세액결정에 영향을 미칠 목적 및 포탈의 고의 | E6: 상 | F6: 핵심 쟁점 | G6: =COUNTIF('05_MAP_F-E-A'!$B$2:$B$2000,A6) -> 4
A7: F-C11-06 | B7: C-11 | C7: F-P | D7: 연도별 포탈세액 합계 (특가법 기준액 판정) | E7: 하 | G7: =COUNTIF('05_MAP_F-E-A'!$B$2:$B$2000,A7) -> 1
A8: F-C11-07 | B8: C-11 | C8: F-P | D8: 세관장 고발 (소추조건) | E8: 하 | G8: =COUNTIF('05_MAP_F-E-A'!$B$2:$B$2000,A8) -> 0
A9: F-C12-01 | B9: C-12 | C9: F-O | D9: 관세 감면을 신청하여 승인받은 사실 | E9: 하 | G9: =COUNTIF('05_MAP_F-E-A'!$B$2:$B$2000,A9) -> 1
A10: F-C12-02 | B10: C-12 | C10: F-O | D10: 부정한 방법의 존재 — 요건 허위, 사실 묵비, 서류 조작 중 특정 | E10: 상 | G10: =COUNTIF('05_MAP_F-E-A'!$B$2:$B$2000,A10) -> 3
A11: F-C12-03 | B11: C-12 | C11: F-O | D11: 감면세액 또는 면탈세액의 산정 | E11: 하 | G11: =COUNTIF('05_MAP_F-E-A'!$B$2:$B$2000,A11) -> 2
A12: F-C12-04 | B12: C-12 | C12: F-S | D12: 부정한 방법에 대한 인식 | E12: 상 | G12: =COUNTIF('05_MAP_F-E-A'!$B$2:$B$2000,A12) -> 2
A13: F-C12-05 | B13: C-12 | C13: F-P | D13: 사후관리 기간 및 위반 여부 | E13: 중 | G13: =COUNTIF('05_MAP_F-E-A'!$B$2:$B$2000,A13) -> 3
A14: F-C13-01 | B14: C-13 | C14: F-O | D14: 환급을 신청하고 수령한 사실 | E14: 하 | G14: =COUNTIF('05_MAP_F-E-A'!$B$2:$B$2000,A14) -> 2
A15: F-C13-02 | B15: C-13 | C15: F-O | D15: 부정한 방법의 존재 — 소요량 과다, 수출사실 부존재, 원재료 불일치 중 특정 | E15: 중 | G15: =COUNTIF('05_MAP_F-E-A'!$B$2:$B$2000,A15) -> 4
A16: F-C13-03 | B16: C-13 | C16: F-O | D16: 정당환급액 산정 및 차액 | E16: 중 | G16: =COUNTIF('05_MAP_F-E-A'!$B$2:$B$2000,A16) -> 2
A17: F-C13-04 | B17: C-13 | C17: F-S | D17: 부정한 방법에 대한 인식 | E17: 상 | G17: =COUNTIF('05_MAP_F-E-A'!$B$2:$B$2000,A17) -> 3
A18: F-C13-05 | B18: C-13 | C18: F-P | D18: 즉시 징수 대상 세액 확정 | E18: 하 | G18: =COUNTIF('05_MAP_F-E-A'!$B$2:$B$2000,A18) -> 1
... A20: F-C14-02 | B20: C-14 | C20: F-O | D20: 가격을 조작한 사실 (실제가격과 신고가격의 괴리) | E20: 중 | G20: =COUNTIF('05_MAP_F-E-A'!$B$2:$B$2000,A20) -> 3
A21: F-C14-03 | B21: C-14 | C21: F-S | D21: 부당하게 재물·재산상 이득을 취득할 목적 | E21: 상 | F21: C-11과의 분기점 (R-C2) | G21: =COUNTIF('05_MAP_F-E-A'!$B$2:$B$2000,A21) -> 4
A22: F-C14-04 | B22: C-14 | C22: F-P | D22: 물품원가 산정 | E22: 하 | G22: =COUNTIF('05_MAP_F-E-A'!$B$2:$B$2000,A22) -> 2
A23: F-C21-01 | B23: C-21 | C23: F-O | D23: 물품이 수입된 사실 (수입의 시기·장소) | E23: 하 | G23: =COUNTIF('05_MAP_F-E-A'!$B$2:$B$2000,A23) -> 4
A24: F-C21-02 | B24: C-21 | C24: F-O | D24: 신고를 하지 않았거나(1호), 신고물품과 실제물품이 다름(2호) | E24: 중 | G24: =COUNTIF('05_MAP_F-E-A'!$B$2:$B$2000,A24) -> 3
A25: F-C21-03 | B25: C-21 | C25: F-O | D25: 물품의 동일성 부정 — 신고물품과 실제물품이 사회통념상 별개 물품임 | E25: 상 | F25: R-C1 분기점 | G25: =COUNTIF('05_MAP_F-E-A'!$B$2:$B$2000,A25) -> 3
A26: F-C21-04 | B26: C-21 | C26: F-S | D26: 무신고·허위신고의 고의 | E26: 상 | G26: =COUNTIF('05_MAP_F-E-A'!$B$2:$B$2000,A26) -> 3
A27: F-C21-05 | B27: C-21 | C27: F-P | D27: 물품원가 및 관세액 (벌금·가중 기준) | E27: 중 | G27: =COUNTIF('05_MAP_F-E-A'!$B$2:$B$2000,A27) -> 2
A28: F-C21-06 | B28: C-21 | C28: F-P | D28: 몰수 대상물품 특정, 몰수 불능 시 추징액(국내도매가격) | E28: 중 | F28: 물품원가와 구분 | G28: =COUNTIF('05_MAP_F-E-A'!$B$2:$B$2000,A28) -> 2
A29: F-C24-01 | B29: C-24 | C29: F-O | D29: 본범(C-21~C-23 등)의 성립 | E29: 상 | F29: 선결 요건 (R-C3) | G29: =COUNTIF('05_MAP_F-E-A'!$B$2:$B$2000,A29) -> 1
A30: F-C24-02 | B30: C-24 | C30: F-O | D30: 취득·양도·운반·보관·알선·감정 중 어느 행위를 하였는지 특정 | E30: 중 | G30: =COUNTIF('05_MAP_F-E-A'!$B$2:$B$2000,A30) -> 4
A31: F-C24-03 | B31: C-24 | C31: F-S | D31: 밀수품이라는 정(情)의 인식 | E31: 상 | F31: 핵심 쟁점 | G31: =COUNTIF('05_MAP_F-E-A'!$B$2:$B$2000,A31) -> 4
A32: F-C24-04 | B32: C-24 | C32: F-P | D32: 물품원가, 몰수·추징 | E32: 중 | G32: =COUNTIF('05_MAP_F-E-A'!$B$2:$B$2000,A32) -> 2
A33: F-C31-01 | B33: C-31 | C33: F-O | D33: 해당 물품이 허가·승인·추천·증명 대상임 (근거법령 특정) | E33: 하 | G33: =COUNTIF('05_MAP_F-E-A'!$B$2:$B$2000,A33) -> 2
A34: F-C31-02 | B34: C-31 | C34: F-O | D34: 요건을 갖추지 않았거나 부정한 방법으로 갖추었음 | E34: 중 | F34: 발급기관 회신이 결정적 | G34: =COUNTIF('05_MAP_F-E-A'!$B$2:$B$2000,A34) -> 3
A35: F-C31-03 | B35: C-31 | C35: F-O | D35: 수입이 이루어진 사실 | E35: 하 | G35: =COUNTIF('05_MAP_F-E-A'!$B$2:$B$2000,A35) -> 2
A36: F-C31-04 | B36: C-31 | C36: F-S | D36: 요건 미비 또는 부정 취득에 대한 인식 | E36: 상 | G36: =COUNTIF('05_MAP_F-E-A'!$B$2:$B$2000,A36) -> 2
A37: F-C41-01 | B37: C-41 | C37: F-O | D37: 타인의 성명·상호로 납세신고가 이루어진 사실 | E37: 하 | G37: =COUNTIF('05_MAP_F-E-A'!$B$2:$B$2000,A37) -> 3
A38: F-C41-02 | B38: C-41 | C38: F-O | D38: 실질 행위자와 명의자의 분리 | E38: 중 | F38: P-15 연결 | G38: =COUNTIF('05_MAP_F-E-A'!$B$2:$B$2000,A38) -> 5
A39: F-C41-03 | B39: C-41 | C39: F-S | D39: 관세 회피·강제집행 면탈 또는 재산상 이득 목적 | E39: 상 | G39: =COUNTIF('05_MAP_F-E-A'!$B$2:$B$2000,A39) -> 3
A40: F-C41-04 | B40: C-41 | C40: F-O | D40: 명의자의 허락 (허락자 처벌 시) | E40: 중 | G40: =COUNTIF('05_MAP_F-E-A'!$B$2:$B$2000,A40) -> 2
A41: F-C61-01 | B41: C-61 | C41: F-O | D41: 거주자–비거주자 간 채권·채무의 발생 | E41: 중 | G41: =COUNTIF('05_MAP_F-E-A'!$B$2:$B$2000,A41) -> 3
...

Sheet 03_E_증거항목
A1: E코드 | B1: 분류 | C1: 증거항목 | D1: 보유주체 | E1: 휘발성 | F1: 기본 게이트 | G1: 비고
A2: E-101 | B2: 신고·통관 | C2: 수입신고필증 | D2: 세관 | E2: 하 | F2: G1
A3: E-102 | B3: 신고·통관 | C3: 수출신고필증 | D3: 세관 | E3: 하 | F3: G1
A4: E-103 | B4: 신고·통관 | C4: 적하목록·화물관리번호 이력 | D4: 세관 | E4: 하 | F4: G1
A5: E-104 | B5: 신고·통관 | C5: 여행자 휴대품 신고·검사기록 | D5: 세관 | E5: 하 | F5: G1
A6: E-105 | B6: 신고·통관 | C6: 특송·우편 통관목록 | D6: 세관 | E6: 하 | F6: G1
A7: E-106 | B7: 신고·통관 | C7: 환급신청·지급내역 | D7: 세관 | E7: 하 | F7: G1
A8: E-107 | B8: 신고·통관 | C8: 감면승인·사후관리대장 | D8: 세관 | E8: 하 | F8: G1
A9: E-108 | B9: 신고·통관 | C9: 통관고유부호 사용이력 | D9: 세관 | E9: 하 | F9: G1
A10: E-109 | B10: 신고·통관 | C10: 요건확인 승인내역 | D10: 세관/요건기관 | E10: 하 | F10: G1 | G10: 진위는 발급기관 회신 필요
A11: E-110 | B11: 신고·통관 | C11: 사전심사 신청·회신 자료 | D11: 세관 | E11: 하 | F11: G1
A12: E-201 | B12: 거래·계약 | C12: 매매계약서·발주서 | D12: 업체 | E12: 중 | F12: G2
A13: E-202 | B13: 거래·계약 | C13: 상업송장 원본·포장명세서 | D13: 업체 | E13: 중 | F13: G2
A14: E-203 | B14: 거래·계약 | C14: 라이선스·기술도입 계약 | D14: 업체 | E14: 중 | F14: G2
A15: E-204 | B15: 거래·계약 | C15: 가격합의문·견적서 | D15: 업체 | E15: 중 | F15: G2
A16: E-205 | B16: 거래·계약 | C16: 별도송금·상계 약정 | D16: 업체 | E16: 중 | F16: G2
A17: E-206 | B17: 거래·계약 | C17: 국내 판매계약·거래명세 | D17: 업체 | E17: 중 | F17: G2
A18: E-301 | B18: 회계·생산 | C18: 총계정원장·매입원장 | D18: 업체 | E18: 하 | F18: G2
A19: E-302 | B19: 회계·생산 | C19: 재고수불부 | D19: 업체 | E19: 하 | F19: G2
A20: E-303 | B20: 회계·생산 | C20: 지급전표·미지급금 명세 | D20: 업체 | E20: 하 | F20: G2
A21: E-304 | B21: 회계·생산 | C21: 고정자산대장·처분전표 | D21: 업체 | E21: 하 | F21: G2
A22: E-305 | B22: 회계·생산 | C22: 이전가격 보고서·그룹 거래정책 | D22: 업체 | E22: 하 | F22: G2 | G22: #업종:전자 자동삽입
A23: E-306 | B23: 회계·생산 | C23: 세금계산서·매출자료 | D23: 업체 | E23: 하 | F23: G2
A24: E-307 | B24: 회계·생산 | C24: 생산일지·작업지시서·BOM | D24: 업체 | E24: 하 | F24: G2
A25: E-308 | B25: 회계·생산 | C25: 소요량계산서·수율·불량률 자료 | D25: 업체 | E25: 하 | F25: G2
A26: E-401 | B26: 물류·운송 | C26: 선하증권·항공운송장 | D26: 선사·항공사 | E26: 중 | F26: G2
A27: E-402 | B27: 물류·운송 | C27: 검량(VGM)·중량증명 | D27: 선사·검량업체 | E27: 중 | F27: G2
A28: E-403 | B28: 물류·운송 | C28: 봉인번호·환적기록 | D28: 선사·터미널 | E28: 상 | F28: G2
A29: E-404 | B29: 물류·운송 | C29: 보세구역 반출입기록·CCTV | D29: 보세구역 운영인 | E29: 상 | F29: G2 | G29: 보존연한 짧음 — 최우선
A30: E-405 | B30: 물류·운송 | C30: 창고 입출고전표 | D30: 물류업체 | E30: 중 | F30: G2
A31: E-406 | B31: 물류·운송 | C31: 배송 운송장 이력 | D31: 택배·특송사 | E31: 상 | F31: G2
A32: E-501 | B32: 현품·감정 | C32: 현품 (유치·압수물) | D32: 세관 | E32: 상 | F32: G2/G4 | G32: 통관 완료 시 확보 곤란
A33: E-502 | B33: 현품·감정 | C33: 성분·구조 감정서 | D33: 분석기관 | E33: 상 | F33: G2
A34: E-503 | B34: 현품·감정 | C34: 제품 사양서·카탈로그 | D34: 업체·제조자 | E34: 중 | F34: G2
A35: E-504 | B35: 현품·감정 | C35: 표시·광고물 | D35: 업체·유통 | E35: 상 | F35: G2
A36: E-505 | B36: 현품·감정 | C36: 권리자 감정서 | D36: 권리자 | E36: 중 | F36: G2
A37: E-601 | B37: 금융·자금 | C37: 외국환 지급·수령내역 | D37: 금융기관 | E37: 하 | F37: G3 | G37: 영장 필요
A38: E-602 | B38: 금융·자금 | C38: 계좌 거래내역 | D38: 금융기관 | E38: 하 | F38: G3 | G38: 영장 필요
A39: E-603 | B39: 금융·자금 | C39: 신용장·T/T 증빙 | D39: 금융기관·업체 | E39: 하 | F39: G2/G3
A40: E-604 | B40: 금융·자금 | C40: FIU 특정금융거래정보 | D40: FIU | E40: 하 | F40: G3 | G40: 요구권이 아닌 제공·통보 체계
...

Sheet 04_A_수집행위
A1: A코드 | B1: 수집행위 | C1: 근거법령 | D1: 게이트 | E1: 산출물 | F1: 소요기간 | G1: 비고
A2: A-01 | B2: 내부 보유자료 조회·대사 | C2: 내부 보유자료 | D2: G1 | E2: 대사표 | F2: 즉시 | G2: 자동화 대상
A3: A-02 | B3: 장부·자료 제출요구 | C3: 관세법 제266조 | D3: G2 | E3: 제출요구서·수령증 | F3: 단기
A4: A-03 | B4: 관계기관 조회·원조요구 | C4: 관세법 제268조 | D4: G2 | E4: 회신문 | F4: 단기
A5: A-04 | B5: 현품검사·시료채취·감정의뢰 | C5: 관세법 제246조·제265조 | D5: G2 | E5: 검사조서·감정서 | F5: 중기
A6: A-05 | B6: 현장확인·실지조사 | C6: 관세법 제266조 | D6: G2 | E6: 실지조사 복명서 | F6: 단기
A7: A-06 | B7: 참고인 진술청취 | C7: 관세법 제291조·제292조 | D7: G2 | E7: 진술조서·확인서 | F7: 단기
A8: A-07 | B8: 해외세관 공조 요청 | C8: CMAA·관세협력협정 | D8: G3 | E8: 공조 회신 | F8: 장기 | G8: R-E6 착수 당일 발송
A9: A-08 | B9: 원산지 검증 요청 | C9: FTA관세특례법 | D9: G3 | E9: 검증 회신 | F9: 장기 | G9: R-E6 착수 당일 발송
A10: A-09 | B10: 금융거래정보 확보 | C10: 금융실명법 (영장) | D10: G3 | E10: 계좌 거래내역 | F10: 중기
A11: A-10 | B11: 통신사실확인자료 확보 | C11: 통신비밀보호법 (허가) | D11: G3 | E11: 통신자료 | F11: 중기
A12: A-11 | B12: 공적장부 조회 | C12: 관세법 제268조·등기 관련 법령 | D12: G2 | E12: 등기부·명부 | F12: 즉시
A13: A-12 | B13: 수색·압수 | C13: 관세법 제296조 (판사 영장) | D13: G4 | E13: 압수조서·압수목록 | F13: 중기 | G13: 범칙전환 필요
A14: A-13 | B14: 디지털 포렌식 | C14: 관세법 제296조 (판사 영장) | D14: G4 | E14: 이미징·해시·분석보고서 | F14: 중기 | G14: 선별압수·참여권 보장
A15: A-14 | B15: 피의자 신문 | C15: 관세법 제290~292조 | D15: G4 | E15: 피의자 신문조서 | F15: 단기 | G15: 진술거부권 고지
A16: A-15 | B16: 통관보류·유치 | C16: 관세법 제235조·제238조 | D16: G2 | E16: 보류통보·유치조서 | F16: 즉시 | G16: 현품 확보 수단
A17: A-16 | B17: FIU 정보 활용 | C17: 특정금융정보법 | D17: G3 | E17: 분석자료 | F17: 중기 | G17: 제공·통보 체계

Sheet 05_MAP_F-E-A
A1: 매핑ID | B1: F코드 | C1: E코드 | D1: 필수구분 | E1: A코드 | F1: 게이트 | G1: 비고 | H1: 증거항목명 | I1: 휘발성
A2: MAP-0001 | B2: F-C11-01 | C2: E-101 | D2: ◎ | E2: A-01 | F2: G1 | H2: 수입신고필증 | I2: 하
A3: MAP-0002 | B3: F-C11-01 | C3: E-103 | D3: ○ | E3: A-01 | F3: G1 | H3: 적하목록·화물관리번호 이력 | I3: 하
A4: MAP-0003 | B4: F-C11-02 | C4: E-1001 | D4: ◎ | E4: A-07 | F4: G3 | G4: 착수 당일 발송 | H4: 수출국 수출신고자료 | I4: 하
A5: MAP-0004 | B5: F-C11-02 | C5: E-202 | D5: ◎ | E5: A-02 | F5: G2 | H5: 상업송장 원본·포장명세서 | I5: 중
A6: MAP-0005 | B6: F-C11-02 | C6: E-601 | D6: ◎ | E6: A-09 | F6: G3 | G6: 영장 필요 | H6: 외국환 지급·수령내역 | I6: 하
A7: MAP-0006 | B7: F-C11-02 | C7: E-204 | D7: ○ | E7: A-02 | F7: G2 | H7: 가격합의문·견적서 | I7: 중
A8: MAP-0007 | B8: F-C11-02 | C8: E-603 | D8: ○ | E8: A-09 | F8: G3 | H8: 신용장·T/T 증빙 | I8: 하
A9: MAP-0008 | B9: F-C11-03 | C9: E-503 | D9: ◎ | E9: A-02 | F9: G2 | H9: 제품 사양서·카탈로그 | I9: 중
A10: MAP-0009 | B10: F-C11-03 | C10: E-501 | D10: ○ | E10: A-04 | F10: G2 | H10: 현품 (유치·압수물) | I10: 상
A11: MAP-0010 | B11: F-C11-03 | C11: E-502 | D11: ○ | E11: A-04 | F11: G2 | H11: 성분·구조 감정서 | I11: 상
A12: MAP-0011 | B12: F-C11-04 | C12: E-101 | D12: ◎ | E12: A-01 | F12: G1 | H12: 수입신고필증 | I12: 하
A13: MAP-0012 | B13: F-C11-04 | C13: E-301 | D13: ◎ | E13: A-02 | F13: G2 | H13: 총계정원장·매입원장 | I13: 하
A14: MAP-0013 | B14: F-C11-04 | C14: E-206 | D14: ○ | E14: A-02 | F14: G2 | H14: 국내 판매계약·거래명세 | I14: 중
A15: MAP-0014 | B15: F-C11-05 | C15: E-801 | D15: ◎ | E15: A-12 | F15: G4 | G15: 고의 입증 | H15: 이메일·메신저 | I15: 상
A16: MAP-0015 | B16: F-C11-05 | C16: E-803 | D16: ◎ | E16: A-13 | F16: G4 | G16: 고의 입증 | H16: 내부 결재·회의자료 | I16: 상
A17: MAP-0016 | B17: F-C11-05 | C17: E-205 | D17: ○ | E17: A-02 | F17: G2 | H17: 별도송금·상계 약정 | I17: 중
A18: MAP-0017 | B18: F-C11-05 | C18: E-901 | D18: ○ | E18: A-14 | F18: G4 | H18: 피의자 신문조서 | I18: 하
A19: MAP-0018 | B19: F-C11-06 | C19: E-101 | D19: ◎ | E19: A-01 | F19: G1 | H19: 수입신고필증 | I19: 하
A20: MAP-0019 | B20: F-C12-01 | C20: E-107 | D20: ◎ | E20: A-01 | F20: G1 | H20: 감면승인·사후관리대장 | I20: 하
A21: MAP-0020 | B21: F-C12-02 | C21: E-107 | D21: ◎ | E21: A-01 | F21: G1 | H21: 감면승인·사후관리대장 | I21: 하
A22: MAP-0021 | B22: F-C12-02 | C22: E-902 | D22: ◎ | E22: A-06 | F22: G2 | H22: 참고인 진술조서 | I22: 하
A23: MAP-0022 | B23: F-C12-02 | C23: E-801 | D23: ○ | E23: A-13 | F23: G4 | H23: 이메일·메신저 | I23: 상
A24: MAP-0023 | B24: F-C12-03 | C24: E-107 | D24: ◎ | E24: A-01 | F24: G1 | H24: 감면승인·사후관리대장 | I24: 하
A25: MAP-0024 | B25: F-C12-03 | C25: E-101 | D25: ◎ | E25: A-01 | F25: G1 | H25: 수입신고필증 | I25: 하
A26: MAP-0025 | B26: F-C12-04 | C26: E-803 | D26: ◎ | E26: A-13 | F26: G4 | G26: 고의 입증 | H26: 내부 결재·회의자료 | I26: 상
A27: MAP-0026 | B27: F-C12-04 | C27: E-901 | D27: ○ | E27: A-14 | F27: G4 | H27: 피의자 신문조서 | I27: 하
A28: MAP-0027 | B28: F-C12-05 | C28: E-304 | D28: ◎ | E28: A-02 | F28: G2 | H28: 고정자산대장·처분전표 | I28: 하
A29: MAP-0028 | B29: F-C12-05 | C29: E-306 | D29: ◎ | E29: A-02 | F29: G2 | H29: 세금계산서·매출자료 | I29: 하
A30: MAP-0029 | B30: F-C12-05 | C30: E-201 | D30: ○ | E30: A-02 | F30: G2 | H30: 매매계약서·발주서 | I30: 중
A31: MAP-0030 | B31: F-C13-01 | C31: E-106 | D31: ◎ | E31: A-01 | F31: G1 | H31: 환급신청·지급내역 | I31: 하
A32: MAP-0031 | B32: F-C13-01 | C32: E-102 | D32: ○ | E32: A-01 | F32: G1 | H32: 수출신고필증 | I32: 하
A33: MAP-0032 | B33: F-C13-02 | C33: E-307 | D33: ◎ | E33: A-02 | F33: G2 | H33: 생산일지·작업지시서·BOM | I33: 하
A34: MAP-0033 | B34: F-C13-02 | C34: E-302 | D34: ◎ | E34: A-02 | F34: G2 | H34: 재고수불부 | I34: 하
A35: MAP-0034 | B35: F-C13-02 | C35: E-405 | D35: ○ | E35: A-02 | F35: G2 | H35: 창고 입출고전표 | I35: 중
A36: MAP-0035 | B36: F-C13-02 | C36: E-902 | D36: ○ | E36: A-06 | F36: G2 | H36: 참고인 진술조서 | I36: 하
A37: MAP-0036 | B37: F-C13-03 | C37: E-308 | D37: ◎ | E37: A-05 | F37: G2 | H37: 소요량계산서·수율·불량률 자료 | I37: 하
A38: MAP-0037 | B38: F-C13-03 | C38: E-307 | D38: ○ | E38: A-02 | F38: G2 | H38: 생산일지·작업지시서·BOM | I38: 하
A39: MAP-0038 | B39: F-C13-04 | C39: E-803 | D39: ◎ | E39: A-13 | F39: G4 | G39: 고의 입증 | H39: 내부 결재·회의자료 | I39: 상
A40: MAP-0039 | B40: F-C13-04 | C40: E-801 | D40: ◎ | E40: A-13 | F40: G4 | G40: 고의 입증 | H40: 이메일·메신저 | I40: 상
...

Sheet 06_P_패턴
A1: P코드 | B1: M코드(수법) | C1: 수법명 | D1: 연결 C코드 | E1: 주구조 | F1: 부구조 | G1: 앵커 | H1: 조건절(요지) | I1: 반증조건 | J1: 호출 축 | K1: 요구 게이트 | L1: 실행구분 | M1: 관측창 유형 | N1: 관측창 값 | O1: 상태
A2: P-001 | B2: M-C11-01 | C2: 저가신고 | D2: C-11 | E2: S1 | F2: S3 | G2: 수입자×HS6 | H2: 신고단가 < 동종물품 하위 10분위 AND 동일 공급자 직전 단가 대비 급락 | I2: 미작성 | J2: A | K2: G1 | L2: 상시탐지 | M2: 고정기간 | N2: 12개월 | O2: 초안
A3: P-002 | B3: M-C11-02 | C3: 허위 인보이스 | D3: C-11 | E3: S4 | G3: 거래쌍 | H3: 인보이스 합계 ≠ 대외 지급액, 차액이 임계 초과 | I3: 미작성 | J3: A·C | K3: G3 | L3: 조사심화 | M3: 고정기간 | N3: 90일 | O3: 초안
A4: P-003 | B4: M-C11-03 | C4: 품명 위장 | D4: C-11 | E4: S3 | G4: 수입자×공급자 | H4: 동일 물품사양 유지 상태에서 신고세번만 저세율로 전환 | I4: 미작성 | J4: A·F | K4: G1 | L4: 상시탐지 | M4: 고정기간 | N4: 36개월 | O4: 초안
A5: P-004 | B5: M-C11-04 | C5: 수량 조작 | D5: C-11 | E5: S1 | G5: 신고건 | H5: 컨테이너 용적·총중량 대비 신고수량 환산 불일치 | I5: 미작성 | J5: A | K5: G1 | L5: 상시탐지 | M5: 단건 | N5: 단건 | O5: 초안
A6: P-005 | B6: M-C11-05 | C6: 원산지 세탁 | D6: C-11 | E6: S1 | F6: S3 | G6: 공급자×경유국 | H6: 제조국–선적국 불일치 AND 특정 시점 이후 경유국 신설 | I6: 미작성 | J6: A·B | K6: G1 | L6: 상시탐지 | M6: 고정기간 | N6: 36개월 | O6: 초안
A7: P-006 | B7: M-C11-06 | C7: 가산요소 누락 | D7: C-11 | E7: S4 | G7: 특수관계 거래쌍 | H7: 로열티·지원비 지급 사실 존재 AND 신고 가산액 부재 | I7: 미작성 | J7: A·C·D | K7: G2 | L7: 조사심화 | M7: 고정기간 | N7: 12개월 | O7: 초안
A8: P-007 | B8: M-C12-01 | C8: 자가사용 위장 | D8: C-12 | E8: S2 | G8: 개인통관부호 | H8: 면세 한도 직하 반복 반입, 동일 품목 누적 수량이 개인 소비 범위 초과 | I8: 미작성 | J8: D | K8: G1 | L8: 상시탐지 | M8: 고정기간 | N8: 90일 | O8: 초안
A9: P-008 | B9: M-C12-02 | C9: 감면 목적 위반 | D9: C-12 | E9: S4 | G9: 감면 승인건 | H9: 감면 용도 신고 AND 사후관리 기간 내 국내 매출·양도 흔적 존재 | I9: 미작성 | J9: A·D·F | K9: G2 | L9: 조사심화 | M9: 이벤트기준 | N9: 사후관리기간 | O9: 초안
A10: P-009 | B10: M-C13-01 | C10: 부정환급 | D10: C-13 | E10: S4 | G10: 환급 신청건 | H10: 수입 원재료 ↔ 소요량 ↔ 수출품 3자 대사에서 연결 결손 | I10: 미작성 | J10: A·F | K10: G1 | L10: 상시탐지 | M10: 고정기간 | N10: 12개월 | O10: 초안
A11: P-010 | B11: M-C13-02 | C11: 과다 환급 | D11: C-13 | E11: S3 | G11: 업체×품목 | H11: 소요량 원단위가 동종업종 분포 상위 이탈 후 유지 | I11: 미작성 | J11: A | K11: G1 | L11: 상시탐지 | M11: 고정기간 | N11: 36개월 | O11: 초안
A12: P-011 | B12: M-C52-01 | C12: 분할 반입(지재권·요건) | D12: C-52 | E12: S2 | G12: 수취인×배송지 | H12: 목록통관·요건 임계 직하 다건, 동일 품목 반복 | I12: 미작성 | J12: B·D | K12: G1 | L12: 상시탐지 | M12: 고정기간 | N12: 90일 | O12: 초안
A13: P-012 | B13: M-C52-02 | C13: 전자상거래 악용 | D13: C-52 | E13: S5 | G13: 배송지·연락처 | H13: 상이한 통관부호 다수가 동일 배송지·연락처 공유 | I13: 미작성 | J13: D | K13: G1 | L13: 상시탐지 | M13: 고정기간 | N13: 12개월 | O13: 초안
A14: P-013 | B14: M-C61-01 | C14: 환치기 | D14: C-61 | E14: S4 | F14: S2 | G14: 계좌군 | H14: 국내 다계좌 소액 분산 입출금 AND 대응 해외송금 기록 부재 | I14: 미작성 | J14: C·D | K14: G3 | L14: 조사심화 | M14: 고정기간 | N14: 90일 | O14: 초안
A15: P-014 | B15: M-C21-01 | C15: 운반책 이용 | D15: C-21 | E15: S5 | F15: S2 | G15: 여행자 | H15: 단기 왕복 반복 AND 항공권 결제자–탑승자 불일치 AND 동일 편 동반자 중복 | I15: 미작성 | J15: B·D | K15: G3 | L15: 조사심화 | M15: 고정기간 | N15: 12개월 | O15: 초안
A16: P-015 | B16: M-C41-01 | C16: 명의 전환(사업자 세탁) | D16: C-41 | E16: S5 | F16: S3 | G16: 사업자 식별자군(대표자·주소·연락처·계좌) | H16: 적발·행정제재 이력 업체와 식별자를 공유하는 신규 사업자가 종전 업체의 거래 속성(공급자·HS·반입지)을 승계한 채 단기간 내 수입 재개 | I16: 적법한 사업 승계·합병·분할 / 정상 재창업 / 세무·통관 대리인 주소 / 공유오피스 주소 | J16: D·A·B | K16: G2 | L16: 조사심화 | M16: 이벤트기준 | N16: 적발 시점 ±36개월 | O16: 초안

Sheet 07_TAG_태그체계
A1: 태그축 | B1: 태그값 | C1: 설명 | D1: 적용 대상
A2: #구조 | B2: S1 | C2: 동시조건형 — 단일 신고건 내 복수 조건 동시 충족 | D2: 패턴
A3: #구조 | B3: S2 | C3: 반복·분할형 — 임계값 직하 소액·소량 다건 반복 | D3: 패턴
A4: #구조 | B4: S3 | C4: 전환형 — 동일 앵커의 과거 행태 대비 급변 | D4: 패턴
A5: #구조 | B5: S4 | C5: 결손·비대칭형 — 존재해야 할 대응 기록이 없음 | D5: 패턴
A6: #구조 | B6: S5 | C6: 공유·군집형 — 독립적이어야 할 주체가 식별자 공유 | D6: 패턴
A7: #앵커 | B7: 수입자 | C7: 패턴이 고정되는 주체·객체 | D7: 패턴
A8: #앵커 | B8: 거래쌍 | C8: 패턴이 고정되는 주체·객체 | D8: 패턴
A9: #앵커 | B9: HS6 | C9: 패턴이 고정되는 주체·객체 | D9: 패턴
A10: #앵커 | B10: 개인통관부호 | C10: 패턴이 고정되는 주체·객체 | D10: 패턴
A11: #앵커 | B11: 배송지 | C11: 패턴이 고정되는 주체·객체 | D11: 패턴
A12: #앵커 | B12: 계좌군 | C12: 패턴이 고정되는 주체·객체 | D12: 패턴
... A48: #상태 | B48: 폐기 | C48: 실행 중단 | D48: 패턴

Sheet 08_G_게이트
A1: 게이트 | B1: 수집행위 유형 | C1: 권한 근거 | D1: 조사 성격 | E1: 자동 실행 | F1: 승인 필요
A2: G1 | B2: 세관 보유 행정자료 대사 (신고·화물·여행자·환급·과세자료) | C2: 내부 보유자료 | D2: － | E2: 가능 | F2: 불요
A3: G2 | B3: 장부·계약·회계자료 제출요구, 현품검사·감정, 관계기관 조회 | C3: 관세법 제266조·제268조 | D3: 임의조사 | E3: 불가 | F3: 내부 결재
A4: G3 | B4: 금융거래정보, 통신자료, 해외 세관 공조·원산지 검증 | C4: 금융실명법, 통신비밀보호법, FTA관세특례법, CMAA | D4: 별도 요건·허가 | E4: 불가 | F4: 영장·허가·공조 절차
A5: G4 | B5: 사업장 수색·압수, 디지털 포렌식, 피의자 신문 | C5: 관세법 제296조, 제290~292조 | D5: 범칙조사(강제) | E5: 불가 | F5: 범칙전환 + 영장

Sheet 09_R_규칙
A1: 규칙ID | B1: 구분 | C1: 규칙명 | D1: 내용 | E1: 위반 시 조치
A2: R1 | B2: 패턴 | C2: 단일수법 | D2: 1 패턴 = 1 수법. 복수 수법 결합은 「복합 시나리오」 계층에서 처리 | E2: 등록 반려
A3: R2 | B3: 패턴 | C3: 구조배타 | D3: 주구조는 S1~S5 중 정확히 하나. 나머지는 부구조로 기재 | E3: 등록 반려
A4: R3 | B4: 패턴 | C4: 게이트분리 | D4: 상시탐지형은 G1 데이터만 사용. G2 이상을 조건절에 쓰면 조사심화형으로 강제 분류 | E4: 자동 재분류
A5: R4 | B5: 패턴 | C5: 반증조건 필수 | D5: 반증조건 없는 패턴은 운영 승인 불가 (초안 상태 고정) | E5: 승인 차단
A6: R5 | B6: 패턴 | C6: 관측창 표준 | D6: 단건 / 90일 / 12개월 / 36개월 / 이벤트기준(±n) 5종만 허용 | E6: 등록 반려
A7: R6 | B7: 패턴 | C7: 임계 외부화 | D7: 조건절에 상수 하드코딩 금지, 파라미터 테이블 참조만 허용 | E7: 등록 반려
A8: R7 | B8: 패턴 | C8: 죄명연결 필수 | D8: 죄명·요증사실에 미연결된 패턴은 증거가이드 생성 대상에서 제외 | E8: 가이드 미생성
A9: R8 | B9: 패턴 | C9: 설명가능성 | D9: 조건절은 원자료로 환원 가능한 술어로만 구성. 학습모델 스코어는 보조지표로만 사용하며 단독 착수 근거 불가 | E9: 착수 승인 차단
A10: R9 | B10: 패턴 | C10: 버전불변 | D10: 운영 중 조건·임계 변경 시 신규 버전 발번. 과거 적중건은 적용 버전 보존 | E10: 자동 발번
A11: R10 | B11: 패턴 | C11: 감쇠관리 | D11: 정밀도가 하한 미달 시 자동 재검토 전환, n분기 연속 미달 시 폐기 상정 | E11: 자동 전환
A12: R-C1 | B12: 죄명 | C12: 허위신고 3분법 | D12: ① 물품 동일성 부정 → C-21 밀수입 / ② 동일성은 인정되나 세액결정 영향 사항 허위 → C-11 관세포탈 / ③ 세액·통관적정 주요사항이 아닌 신고사항 허위 → C-34 허위신고. 동일성 판단은 자동화하지 않고 조사관 확인 항목으로 제시 | E12: 조사관 확인 필수
... A23: R-E7 | B23: 증거 | C23: 채번 연동 | D23: E 확보 시 증거목록 번호를 자동 채번하고 범죄일람표 「증거」란에 역참조 | E23: 자동 연동
